Workbook

Sheet 26년 상반기 예산안
B2: ■ 26년도 운영예산안 _ (보고 : 20251218)
B4: 구분 | C4: 콘텐츠 | D4: 상세 | E4: 수량 | F4: 단위 | G4: 횟수 | H4: 단위 | I4: 단가 | J4: 금액 | K4: 비고
B5: 최초 1회 청구 | C5: 1월 사전세팅 | D5: 사전기획비 | E5: 1 | F5: Series | G5: 1 | H5: 회 | I5: 200000 | J5: =E5*G5*I5 -> 200000
D6: 디자인 제작비 | E6: 1 | F6: Series | G6: 3 | H6: 건 | I6: 600000 | J6: =E6*G6*I6 -> 1800000 | K6: *1월 사전세팅 단계에서, 최초 1회만 청구
B7: SUM | J7: =sum(J5:J6) -> 2000000
B9: 정기 콘텐츠 / 월 기준
B10: -. 비정기 콘텐츠의 경우, 월 1건을 기본으로 비용 산정 -. 해당 월 미진행시 제작수량 이월
B11: 구분 | C11: 콘텐츠 | D11: 상세 | E11: 수량 | F11: 단위 | G11: 횟수 | H11: 단위 | I11: 단가 | J11: 금액 | K11: 비고
B12: 정기 콘텐츠 | C12: 고객인터뷰형 (*순당포착) [구성] 캐러셀1+숏폼2 | D12: 기획 | E12: 1 | F12: Series | G12: 1 | H12: 회 | I12: 200000 | J12: =E12*G12*I12 -> 200000 | K12: 인물 기획, 질문지 구성
D13: 섭외/로케이션 | E13: 1 | F13: Series | G13: 1 | H13: 회 | I13: 300000 | J13: =E13*G13*I13 -> 300000 | K13: 출연자 섭외, 장소 헌팅
D14: 촬영 (화보+인터뷰) | E14: 1 | F14: Series | G14: 2 | H14: set | I14: 300000 | J14: =E14*G14*I14 -> 600000 | K14: 스틸컷+영상 동시 촬영
D15: 사진보정 | E15: 1 | F15: Series | G15: 3 | H15: 이미지 | I15: 100000 | J15: =E15*G15*I15 -> 300000 | K15: 인물 당, 화보이미지 3장 (*이미지 추가 보정 시, 비용 별도 협의)
D16: 영상 편집 | E16: 1 | F16: Series | G16: 2 | H16: 숏폼 | I16: 400000 | J16: =E16*G16*I16 -> 800000 | K16: 숏폼 2건 (#1 라이프스타일 30'' / #2 인터뷰 50'')
C17: 소계 ① | J17: =sum(J12:J16) -> 2200000
C18: 먹방토크형 (*취하지아니한가) [구성] 숏폼3 | D18: 기획 | E18: 1 | F18: Series | G18: 1 | H18: 회 | I18: 300000 | J18: =E18*G18*I18 -> 300000 | K18: 내용 관련 정보 스터디, 질문지 구성
D19: 인물 출연료 | E19: 1 | F19: Series | G19: 2 | H19: 인 | I19: 300000 | J19: =E19*G19*I19 -> 600000 | K19: *평균가, 호스트(외국인,고정) ↔ 게스트(시리즈 별 교체)
D20: 촬영 | E20: 1 | F20: Series | G20: 2 | H20: set | I20: 300000 | J20: =E20*G20*I20 -> 600000
D21: 영상 편집 | E21: 1 | F21: Series | G21: 3 | H21: 숏폼 | I21: 400000 | J21: =E21*G21*I21 -> 1200000
C22: 소계 ② | J22: =sum(J18:J21) -> 2700000
C23: TPO공감형 (*1막1장) [구성] 숏폼2 | D23: 기획 | E23: 1 | F23: Series | G23: 1 | H23: 회 | I23: 200000 | J23: =E23*G23*I23 -> 200000 | K23: 컨셉 구성, 시놉시스 구성
D24: 촬영 | E24: 1 | F24: Series | G24: 1 | H24: 회 | I24: 300000 | J24: 600000
D25: 영상 편집 | E25: 1 | F25: Series | G25: 2 | H25: 숏폼 | I25: 400000 | J25: =E25*G25*I25 -> 800000
C26: 소계 ③ | J26: =sum(J23:J25) -> 1600000
B27: 비정기 콘텐츠 | C27: AI 스터디 | D27: 기획 / 프롬프트 지원 | E27: 1 | F27: Series | G27: 1 | H27: 회 | I27: 200000 | J27: =E27*G27*I27 -> 200000 | K27: AI작업툴 스터디, 컨셉 기획, 프롬프트 설계
D28: AI 제작 지원 | E28: 1 | F28: Series | G28: 1 | H28: 회 | I28: 250000 | J28: =E28*G28*I28 -> 250000 | K28: 이미지 Upscale 및 후보정 (*영상 10초 이상 분량, 비용 별도 협의)
C29: 소계 ④ | J29: =sum(J27:J28) -> 450000
C30: 홍보/이벤트 | D30: 기획 및 소재제작 | E30: 1 | F30: Series | G30: 1 | H30: 회 | I30: 200000 | J30: =E30*G30*I30 -> 200000 | K30: 이미지 2장 기준 (*초과 분량 별도 협의)
D31: 이벤트 운영 지원 | E31: 1 | F31: Series | G31: 1 | H31: 회 | I31: 200000 | J31: =E31*G31*I31 -> 200000 | K31: 당첨자 선정, 경품 발송 등 업무 지원 (*경품비 별도)
C32: 소계 ④ | J32: =sum(J30:J31) -> 400000
B33: 채널 운영 및 콘텐츠 업로드 지원 | J33: 200000
B34: 최종 합계 | J34: =J17+J22+J26+J29+J32+J33-50000 -> 7500000 | K34: *만 단위 절삭
B36: 비정기 콘텐츠 상세 견적
B37: -. 비정기콘텐츠 / 초과 분에 대한 비용가이드
B38: 비정기 콘텐츠 | C38: AI 스터디 | D38: 기획 / 프롬프트 지원 | E38: 1 | F38: Series | G38: 1 | H38: 회 | I38: 200000 | J38: =E38*G38*I38 -> 200000 | K38: 컨셉 기획, 프롬프트 설계
D39: AI 제작 지원 [이미지] | E39: 1 | F39: Series | G39: 1 | H39: 회 | I39: 250000 | J39: =E39*G39*I39 -> 250000 | K39: 이미지 Upscale, 후보정
D40: AI 제작/편집 지원 [영상 10초↓] | E40: 1 | F40: Series | G40: 1 | H40: 회 | I40: 250000 | J40: =E40*G40*I40 -> 250000 | K40: 영상 Upscale
D41: AI 제작/편집 지원 [영상 10초↑] | E41: 1 | F41: Series | G41: 1 | H41: 회 | I41: - | J41: - | K41: *내용에 따라 별도 협의
C42: 홍보/이벤트 | D42: 홍보/이벤트 기획 | E42: 1 | F42: Series | G42: 1 | H42: 회 | I42: 100000 | J42: =E42*G42*I42 -> 100000
D43: 소재 제작 [이미지] | E43: 1 | F43: Series | G43: 1 | H43: 회 | I43: 100000 | J43: =E43*G43*I43 -> 100000 | K43: 이미지(캐러셀) 소재제작
D44: 소재 제작 [영상] | E44: 1 | F44: Series | G44: 1 | H44: 회 | I44: 800000 | J44: =E44*G44*I44 -> 800000 | K44: 영상(릴스)형 콘텐츠 제작
...

Sheet 콘텐츠별세부단가
B1: 2026년 국순당 콘텐츠별 세부 단가표
B3: 1. 막걸리 AI (MAi) — 편당 500,000원
B5: 항목 | C5: 단가 | D5: 비고
B6: AI 기획/프롬프트 | C6: 150000 | D6: 컨셉 기획, 프롬프트 설계
B7: AI 제작/편집 | C7: 350000 | D7: 이미지/모션 생성, 후보정, 자막
B8: 편당 합계 | C8: =SUM(C6:C7) -> 500000
B9: 월 소계 (2회) | C9: =C8*2 -> 1000000 | D9: 이미지 1 + 숏츠 1
B11: 2. 순당포착 — 월 1회 촬영 턴키 2,100,000원 (3개 콘텐츠)
B13: 항목 | C13: 단가 | D13: 비고
B14: 답사 및 촬영 기획 | C14: 200000 | D14: 인물 기획, 질문지 구성
B15: 사전 기획 (인터뷰) | C15: 200000 | D15: 출연자 섭외, 장소 헌팅
B16: 촬영 (인물+인터뷰) | C16: 600000 | D16: 스틸+영상 동시 촬영, 2인 투입
B17: 사진 보정 | C17: 300000 | D17: 피드용 화보 컷 2~3장 보정
B18: 영상 편집 | C18: 800000 | D18: 인터뷰 숏폼 1편 (50) / 스토리콘텐츠 1편 (30)
B19: 월 소계 (3회) | C19: =SUM(C14:C18) -> 2100000 | D19: 1촬영 → 3콘텐츠(이미지형1+영상형2) 세트
B20: ※ 콘텐츠 분리 불가, 세트 턴키로 산정
B22: 3. 막시 + 먹방 — 촬영 1회당 2,200,000원 (2~3개 콘텐츠)
B24: 항목 | C24: 단가 | D24: 비고
B25: 기획 | C25: 300000 | D25: *연속된 콘텐츠는 아님.
B26: 출연료 | C26: 500000 | D26: 출연자 또는 협찬 조율 월 2회 촬영 기준 *기본적으로는 막시 1회 / 막먹 1회 촬영 *각 콘텐츠 당 [4h*시간당 ₩30,000] *회당 2~3개 콘텐츠분 촬영 기준 ₩120,000*2.5개*2회=₩600,000 예상
B27: 촬영 | C27: 600000 | D27: 1회 촬영 시 → 2~3개 콘텐츠분 촬영 *연속된 콘텐츠는 아님.
B28: 편집 (3편) | C28: 800000 | D28: 편당 약 266,667원 (세트 할인 적용) *별도 제작 시 하단 개별요청 편집비 기준표 참조
B29: 촬영 1회 소계 | C29: =SUM(C25:C28) -> 2200000 | D29: 1회 촬영 당 2~3개 콘텐츠 *편당 섭외비 제외 약 평균 700,000원의 예상단가
B30: 월 소계 (2회 촬영) | C30: =C29*2 -> 4400000 | D30: 월 5~6개 콘텐츠
B31: ※ 촬영 횟수 기준 과금, 편당 분리 시 편집비 400,000원/편 적용
B33: 4. 미션형 / 비하인드 — 편당 800,000원
B35: 항목 | C35: 단가 | D35: 비고
B36: 기획/시나리오 | C36: 150000 | D36: 콘텐츠 기획, 레퍼런스 탐색
B37: 촬영지원 | C37: 250000 | D37: 간단 촬영 또는 동행 촬영
B38: 편집 | C38: 400000 | D38: (Pre) 기획/시나리오 + (Post) 편집 작업을 통합
B39: 편당 합계 | C39: =SUM(C36:C38) -> 800000
B40: 월 소계 (1회) | C40: =C39*1 -> 800000
B42: ※ 프로젝트 시즌(상/하반기) 비중 증가 가능
B44: ■ 편집비 기준표 (개별 요청 시)
B46: 유형 | C46: 편집비 (편당) | D46: 비고
B47: 영상 (숏폼) | C47: 400000 | D47: 정가 기준
B48: 이미지/카드뉴스 | C48: 200000 | D48: 보정 포함
B49: 촬영지원 | C49: 480000
B50: AI 제작물 | C50: 350000

Sheet (InactivE) 월간비용총괄
B1: 2026년 국순당 SNS 콘텐츠 제작 견적
B3: ■ 월간 콘텐츠 비용 총괄 (4주 기준 / 5주차는 월별 상이하므로 추가반영)
B5: 콘텐츠 | C5: 월 편성 | D5: 제작 구조 | E5: 편당 단가 | F5: 월 소계 | G5: 비고
B6: 막걸리 AI (MAi) | C6: 2 | D6: 편당 정가 | E6: 500000 | F6: =C6*E6 -> 1000000 | G6: 이미지 1 + 숏츠 1
B7: 순당포착 | C7: 3 | D7: 월 1회 촬영 턴키 | E7: (턴키) | F7: ='콘텐츠별세부단가'!$C$19 -> 2100000 | G7: 화보+영상+스토리 세트
B8: 막시 + 먹방 | C8: 6 | D8: 월 2회 촬영 (5~6회분 제작) 턴키 | E8: (턴키) | F8: ='콘텐츠별세부단가'!$C$30 -> 4400000 | G8: 촬영당 2,000,000
B9: 미션형/비하인드 | C9: 1 | D9: 편당 정가 | E9: 800000 | F9: =C9*E9 -> 800000 | G9: 기존 구조 + 편집비↑
B10: 월 콘텐츠 소계 | C10: =SUM(C6:C9) -> 12 | F10: =SUM(F6:F9) -> 8300000
B11: 대행수수료 | C11: - | D11: 월 고정 | F11: 200000 | G11: 콘텐츠PM/운영관리/섭외 등을 포함
B12: 월 총계 | F12: =F10+F11 -> 8500000
B14: 수정 [주2회 반영 (AI는 별도)]
B15: 콘텐츠 | C15: 월 편성 | D15: 제작 구조 | E15: 편당 단가 | F15: 월 소계 | G15: 비고
B16: 시리즈 A : 순당포착 | C16: 3 | D16: 월 1회 촬영 턴키 | E16: (턴키) | F16: ='콘텐츠별세부단가'!$C$19 -> 2100000 | G16: 화보+영상+스토리 세트
B17: 시리즈 B : 외국인 | C17: 3 | D17: (가제) 어느날 외국인이 막걸리를 들고왔다 | E17: (턴키) | F17: ='콘텐츠별세부단가'!$C$29 -> 2200000
B18: 시리즈 C : 추가시리즈 | C18: 2 | E18: (턴키) | F18: ='콘텐츠별세부단가'!$C$29 -> 2200000
B19: 월 콘텐츠 소계 | C19: =SUM(C15:C18) -> 8 | F19: =SUM(F15:F18) -> 6500000
B20: 막걸리 AI (MAi) | C20: 2 | D20: 편당 정가 | E20: 500000 | F20: =C20*E20 -> 1000000 | G20: 이미지 1 + 숏츠 1
B21: 대행수수료 | C21: - | D21: 월 고정 | F21: 200000 | G21: 콘텐츠PM/운영관리/섭외 등을 포함
B22: 월 총계 | F22: =sum(F19:F21) -> 7700000 | G22: 추가 요청시 별도 적용
B25: ■ 1월 사전준비 비용 (별도)
B27: 항목 | C27: 금액 | D27: 비고
B28: 사전 기획비 | C28: 1000000 | D28: 연간 방향성 수립, 콘텐츠 시리즈 기획 *막시/막먹 출연자 사전 컨택/섭외에 따른 인건비 포함
B29: 디자인비 | C29: 1000000 | D29: 각 시리즈별 디자인 그래픽 제작
B30: 1월 총계 | C30: =SUM(C28:C29) -> 2000000 | D30: 본격 촬영 전 선행 비용
B32: ■ 예상 광고비 (월)
B33: 항목 | C33: 금액 | D33: 비고
B34: 인스타그램 | C34: 300000 | D34: 12개 콘텐츠 중 시리즈별 1개분 약 3~4개분에 대해 광고 진행하여 건당 5~8만원 집행
B35: 총계 | C35: =SUM(C34) -> 300000 | D35: 유튜브 운영 시 재편성
